<?xml version="1.0"?>
<robot name="motoman_sia10f"
       xmlns:xi="http://www.w3.org/2001/XInclude">
  <link name="base_link">
    <visual>
      <origin xyz="0 0 0" rpy="0 -0 0"/>
      <geometry>
        <mesh filename="file:///tmp/base_link_mesh.dae" scale="1 1 1" />
      </geometry>
    </visual>
    <collision>
      <origin xyz="0 0 0" rpy="0 -0 0"/>
      <geometry>
        <mesh filename="file:///tmp/base_link_mesh.dae" scale="1 1 1" />
      </geometry>
    </collision>
  </link>
  <link name="link_s">
    <visual>
      <origin xyz="0 0 0.36" rpy="0 -0 0"/>
      <geometry>
        <mesh filename="file:///tmp/link_s_mesh.dae" scale="1 1 1" />
      </geometry>
    </visual>
    <collision>
      <origin xyz="0 0 0.36" rpy="0 -0 0"/>
      <geometry>
        <mesh filename="file:///tmp/link_s_mesh.dae" scale="1 1 1" />
      </geometry>
    </collision>
  </link>
  <link name="link_l">
    <visual>
      <origin xyz="0 0 0" rpy="0 -0 0"/>
      <geometry>
        <mesh filename="file:///tmp/link_l_mesh.dae" scale="1 1 1" />
      </geometry>
    </visual>
    <collision>
      <origin xyz="0 0 0" rpy="0 -0 0"/>
      <geometry>
        <mesh filename="file:///tmp/link_l_mesh.dae" scale="1 1 1" />
      </geometry>
    </collision>
  </link>
  <link name="link_e">
    <visual>
      <origin xyz="0 0 0.36" rpy="0 -0 0"/>
      <geometry>
        <mesh filename="file:///tmp/link_e_mesh.dae" scale="1 1 1" />
      </geometry>
    </visual>
    <collision>
      <origin xyz="0 0 0.36" rpy="0 -0 0"/>
      <geometry>
        <mesh filename="file:///tmp/link_e_mesh.dae" scale="1 1 1" />
      </geometry>
    </collision>
  </link>
  <link name="link_u">
    <visual>
      <origin xyz="0 0 0" rpy="0 -0 0"/>
      <geometry>
        <mesh filename="file:///tmp/link_u_mesh.dae" scale="1 1 1" />
      </geometry>
    </visual>
    <collision>
      <origin xyz="0 0 0" rpy="0 -0 0"/>
      <geometry>
        <mesh filename="file:///tmp/link_u_mesh.dae" scale="1 1 1" />
      </geometry>
    </collision>
  </link>
  <link name="link_r">
    <visual>
      <origin xyz="0 0 0.36" rpy="0 -0 0"/>
      <geometry>
        <mesh filename="file:///tmp/link_r_mesh.dae" scale="1 1 1" />
      </geometry>
    </visual>
    <collision>
      <origin xyz="0 0 0.36" rpy="0 -0 0"/>
      <geometry>
        <mesh filename="file:///tmp/link_r_mesh.dae" scale="1 1 1" />
      </geometry>
    </collision>
  </link>
  <link name="link_b">
    <visual>
      <origin xyz="0 0 0" rpy="0 -0 0"/>
      <geometry>
        <mesh filename="file:///tmp/link_b_mesh.dae" scale="1 1 1" />
      </geometry>
    </visual>
    <collision>
      <origin xyz="0 0 0" rpy="0 -0 0"/>
      <geometry>
        <mesh filename="file:///tmp/link_b_mesh.dae" scale="1 1 1" />
      </geometry>
    </collision>
  </link>
  <link name="link_t">
    <visual>
      <origin xyz="0 0 0.155" rpy="0 -0 0"/>
      <geometry>
        <mesh filename="file:///tmp/link_t_mesh.dae" scale="1 1 1" />
      </geometry>
    </visual>
    <collision>
      <origin xyz="0 0 0.155" rpy="0 -0 0"/>
      <geometry>
        <mesh filename="file:///tmp/link_t_mesh.dae" scale="1 1 1" />
      </geometry>
    </collision>
  </link>
  <link name="tool0">
  </link>
  <link name="base">
  </link>
  <joint name="joint_s" type="revolute">
    <parent link="base_link"/>
    <child  link="link_s"/>
    <origin xyz="0 0 0.36" rpy="0 -0 0 "/>
    <axis   xyz="0 0 1"/>
    <limit lower="-3.1415" upper="3.1415" effort="100" velocity="2.967" />
    <dynamics damping="0.2" friction="0" />
  </joint>
  <joint name="joint_l" type="revolute">
    <parent link="link_s"/>
    <child  link="link_l"/>
    <origin xyz="0 0 0" rpy="0 -0 0 "/>
    <axis   xyz="0 1 0"/>
    <limit lower="-1.9198" upper="1.9198" effort="100" velocity="2.967" />
    <dynamics damping="0.2" friction="0" />
  </joint>
  <joint name="joint_e" type="revolute">
    <parent link="link_l"/>
    <child  link="link_e"/>
    <origin xyz="0 0 0.36" rpy="0 -0 0 "/>
    <axis   xyz="0 0 1"/>
    <limit lower="-2.967" upper="2.967" effort="100" velocity="2.967" />
    <dynamics damping="0.2" friction="0" />
  </joint>
  <joint name="joint_u" type="revolute">
    <parent link="link_e"/>
    <child  link="link_u"/>
    <origin xyz="0 0 0" rpy="0 -0 0 "/>
    <axis   xyz="0 -1 0"/>
    <limit lower="-2.3561" upper="2.3561" effort="100" velocity="2.967" />
    <dynamics damping="0.2" friction="0" />
  </joint>
  <joint name="joint_r" type="revolute">
    <parent link="link_u"/>
    <child  link="link_r"/>
    <origin xyz="0 0 0.36" rpy="0 -0 0 "/>
    <axis   xyz="0 0 -1"/>
    <limit lower="-3.1415" upper="3.1415" effort="100" velocity="3.4906" />
    <dynamics damping="0.2" friction="0" />
  </joint>
  <joint name="joint_b" type="revolute">
    <parent link="link_r"/>
    <child  link="link_b"/>
    <origin xyz="0 0 0" rpy="0 -0 0 "/>
    <axis   xyz="0 -1 0"/>
    <limit lower="-1.9198" upper="1.9198" effort="100" velocity="3.4906" />
    <dynamics damping="0.2" friction="0" />
  </joint>
  <joint name="joint_t" type="revolute">
    <parent link="link_b"/>
    <child  link="link_t"/>
    <origin xyz="0 0 0.155" rpy="0 -0 0 "/>
    <axis   xyz="0 0 -1"/>
    <limit lower="-3.1415" upper="3.1415" effort="100" velocity="6.9813" />
    <dynamics damping="0.2" friction="0" />
  </joint>
  <joint name="link_t-tool0" type="fixed">
    <parent link="link_t"/>
    <child  link="tool0"/>
    <origin xyz="0 0 0" rpy="0 -0 0 "/>
    <axis   xyz="0 0 0"/>
    <limit lower="0" upper="0" effort="100" velocity="0.5" />
    <dynamics damping="0.2" friction="0" />
  </joint>
  <joint name="link_l-base" type="fixed">
    <parent link="link_l"/>
    <child  link="base"/>
    <origin xyz="0 0 0" rpy="0 -0 0 "/>
    <axis   xyz="0 0 0"/>
    <limit lower="0" upper="0" effort="100" velocity="0.5" />
    <dynamics damping="0.2" friction="0" />
  </joint>
</robot>
